/**
 * Error Recovery Service
 * Graceful error handling and recovery with rollback capabilities
 */

import { EventEmitter } from 'events';
import pino from 'pino';

import type { 
  DevServerConfig, 
  RecoveryAction, 
  ErrorContext 
} from '../types/index.js';

export class ErrorRecoveryService extends EventEmitter {
  private config: DevServerConfig;
  private logger: pino.Logger;
  private recoveryActions = new Map<string, RecoveryAction[]>();
  private errorHistory: ErrorContext[] = [];

  constructor(config: DevServerConfig, logger?: pino.Logger) {
    super();
    this.config = config;
    this.logger = logger || pino({ name: 'ErrorRecovery' });
  }

  async initialize(): Promise<void> {
    this.logger.info('Error recovery system initialized');
  }

  async handleError(error: Error, context?: any): Promise<void> {
    const errorContext: ErrorContext = {
      error,
      operation: context?.operation || 'unknown',
      timestamp: new Date(),
      attempts: 0,
      resolved: false,
      ...context
    };

    this.errorHistory.push(errorContext);
    this.logger.error('Error occurred', { error: error.message, context });

    // Attempt recovery if enabled
    if (this.config.errorRecovery.enabled && this.config.errorRecovery.automaticRecovery) {
      await this.attemptRecovery(errorContext);
    }
  }

  private async attemptRecovery(context: ErrorContext): Promise<void> {
    // Simple recovery logic - would be more sophisticated in real implementation
    this.logger.info('Attempting error recovery', { operation: context.operation });
    
    // Mark as resolved for now
    context.resolved = true;
    this.emit('error-recovered', {
      id: 'recovery-1',
      type: 'reload-module',
      description: 'Attempted module reload',
      automatic: true,
      timeoutMs: 5000,
      execute: async () => true
    });
  }
}